Workbook

Sheet Performance LD
A1: In Class Case Study Model
A3: Technology | C3: Wind Energy Turbine
A5: Capacity | C5: =+'[1]Base Data'!D5 -> MW | E5: 72
A6: Capacity Factor: Note 2 | C6: =+'[1]Base Data'!D15 -> % | E6: =VLOOKUP('Performance LD'!A6,Table1[#All],8,FALSE) -> 0.4
A7: Annual Production | C7: MWH | E7: =+E5*8760*E6 -> 252288
A8: Heat Rate/Fuel Rate | C8: btu/kwh | E8: =VLOOKUP('Performance LD'!A8,Table1[#All],8,FALSE) -> 0
A9: Fixed O&M | C9: $/kw/yr | E9: =VLOOKUP('Performance LD'!A9,Table1[#All],8,FALSE) -> 42
A10: Variable O&M | C10: $/mwh | E10: =VLOOKUP('Performance LD'!A10,Table1[#All],8,FALSE) -> 0
A11: Capital Cost: Note 1 | C11: =+'[1]Base Data'!D6 -> $/kw | E11: =VLOOKUP('Performance LD'!A11,Table1[#All],8,FALSE) -> 1500
A12: EPC Capital Cost* | C12: $mm | E12: =+E5*E11*1000/1000000 -> 108
A13: Construction Debt Term | C13: Yrs | E13: =VLOOKUP('Performance LD'!A13,Table1[#All],8,FALSE) -> 3
A14: S Curve for EPC Capital Cost* | C14: Yr | E14: Y1 | F14: Yr2 | G14: Yr3
A15: S Curve for EPC Capital Cost* | C15: % | E15: 0.1 | F15: 0.4 | G15: 0.5
A16: S Curve for EPC Capital Cost* | C16: $mm | E16: =+E12*E15 -> 10.8 | F16: =+E12*F15 -> 43.2 | G16: =+E12*G15 -> 54
A17: Cost Inflation Rate | C17: % | E17: =VLOOKUP('Performance LD'!A17,Table1[#All],8,FALSE) -> 0.025
A18: Economic Life | C18: Years | E18: =VLOOKUP('Performance LD'!A18,Table1[#All],8,FALSE) -> 25
A19: Tax Rate | C19: Federal | E19: =VLOOKUP('Performance LD'!A19,Table1[#All],8,FALSE) -> 0.21
A20: Tax Depreciation | C20: MACRS | E20: =VLOOKUP('Performance LD'!A20,Table1[#All],8,FALSE) -> 5 | H20: Year 1 | I20: Year 2 | J20: Year 3 | K20: Year 4 | L20: Year 5 | M20: Year 6
A21: Tax Depreciation Rate | C21: % | H21: 0.2 | I21: 0.32 | J21: 0.192 | K21: 0.1152 | L21: 0.1152 | M21: 0.0576
A22: CO2 Emissions | C22: lbs/mmbtu | E22: 0
A23: Potential Carbon Tax | C23: $/ton | E23: 0
A25: *Excludes any development fee or interest during construction
A28: Development Fee Bonus
A30: Development Fee Bonus | C30: % EPC Capital Cost | E30: 0.05
A31: Development Fee Bonus | C31: $mm | E31: =+E30*E12 -> 5.4
A32: Capital Cost Including Development Fee | E32: =+E12+E31 -> 113.4
A33: S Curve for Total Capital Cost** | C33: Yr | E33: Yr1 | F33: Yr2 | G33: Yr3
A34: S Curve for Total Capital Cost** | C34: % | E34: 0.1 | F34: 0.4 | G34: 0.5
A35: S Curve for Total Capital Cost** | C35: $mm | E35: =+E34*$E$32 -> 11.34 | F35: =+F34*$E$32 -> 45.36 | G35: =+G34*$E$32 -> 56.7
A37: **Includes development fee but excludes interest during construction
A40: Construction Finance and Take Out Finance
A42: Construction Debt Term | C42: Yrs | E42: 3
A43: Construction Debt Rate | C43: % | E43: 0.05
A44: Construction Debt Leverage | C44: % | E44: 0.5
A46: Take-Out Debt Term | C46: Yrs | E46: 15
A47: Take-Out Debt Rate | C47: % | E47: 0.065
A48: Take-Out Debt Leverage | C48: % | E48: 0.59555421
A50: Take Out Debt is to be structrued with a mortgage style amortization with
A51: equal debt service amounts over the entire take-out term of 15 years
A53: In addition to the capital cost from the EPC contract and the Development Fee Bonus
...

Sheet Schedule LD
A1: In Class Case Study Model
A3: Technology | C3: Wind Energy Turbine
A5: Capacity | C5: =+'[1]Base Data'!D5 -> MW | E5: =VLOOKUP('Schedule LD'!A5,Table1[#All],8,FALSE) -> 80
A6: Capacity Factor: Note 2 | C6: =+'[1]Base Data'!D15 -> % | E6: =VLOOKUP('Schedule LD'!A6,Table1[#All],8,FALSE) -> 0.4
A7: Annual Production | C7: MWH | E7: =+E5*8760*E6 -> 280320
A8: Heat Rate/Fuel Rate | C8: btu/kwh | E8: =VLOOKUP('Schedule LD'!A8,Table1[#All],8,FALSE) -> 0
A9: Fixed O&M | C9: $/kw/yr | E9: =VLOOKUP('Schedule LD'!A9,Table1[#All],8,FALSE) -> 42
A10: Variable O&M | C10: $/mwh | E10: =VLOOKUP('Schedule LD'!A10,Table1[#All],8,FALSE) -> 0
A11: Capital Cost: Note 1 | C11: =+'[1]Base Data'!D6 -> $/kw | E11: =VLOOKUP('Schedule LD'!A11,Table1[#All],8,FALSE) -> 1500
A12: EPC Capital Cost* | C12: $mm | E12: =+E5*E11*1000/1000000 -> 120
A13: Construction Debt Term | C13: Yrs | E13: =VLOOKUP('Schedule LD'!A13,Table1[#All],8,FALSE) -> 3
A14: S Curve for EPC Capital Cost* | C14: Yr | E14: Y1 | F14: Yr2 | G14: Yr3
A15: S Curve for EPC Capital Cost* | C15: % | E15: 0.1 | F15: 0.4 | G15: 0.5
A16: S Curve for EPC Capital Cost* | C16: $mm | E16: =+E12*E15 -> 12 | F16: =+E12*F15 -> 48 | G16: =+E12*G15 -> 60
A17: Cost Inflation Rate | C17: % | E17: =VLOOKUP('Schedule LD'!A17,Table1[#All],8,FALSE) -> 0.025
A18: Economic Life | C18: Years | E18: =VLOOKUP('Schedule LD'!A18,Table1[#All],8,FALSE) -> 25
A19: Tax Rate | C19: Federal | E19: =VLOOKUP('Schedule LD'!A19,Table1[#All],8,FALSE) -> 0.21
A20: Tax Depreciation | C20: MACRS | E20: =VLOOKUP('Schedule LD'!A20,Table1[#All],8,FALSE) -> 5 | H20: Year 1 | I20: Year 2 | J20: Year 3 | K20: Year 4 | L20: Year 5 | M20: Year 6
A21: Tax Depreciation Rate | C21: % | H21: 0.2 | I21: 0.32 | J21: 0.192 | K21: 0.1152 | L21: 0.1152 | M21: 0.0576
A22: CO2 Emissions | C22: lbs/mmbtu | E22: 0
A23: Potential Carbon Tax | C23: $/ton | E23: 0
A25: *Excludes any development fee or interest during construction
A28: Development Fee Bonus
A30: Development Fee Bonus | C30: % EPC Capital Cost | E30: 0.05
A31: Development Fee Bonus | C31: $mm | E31: =+E30*E12 -> 6
A32: Capital Cost Including Development Fee | E32: =+E12+E31 -> 126
A33: S Curve for Total Capital Cost** | C33: Yr | E33: Yr1 | F33: Yr2 | G33: Yr3
A34: S Curve for Total Capital Cost** | C34: % | E34: 0.1 | F34: 0.4 | G34: 0.5
A35: S Curve for Total Capital Cost** | C35: $mm | E35: =+E34*$E$32 -> 12.6 | F35: =+F34*$E$32 -> 50.4 | G35: =+G34*$E$32 -> 63
A37: **Includes development fee but excludes interest during construction
A40: Construction Finance and Take Out Finance
A42: Construction Debt Term | C42: Yrs | E42: 3
A43: Construction Debt Rate | C43: % | E43: 0.05
A44: Construction Debt Leverage | C44: % | E44: 0.5
A46: Take-Out Debt Term | C46: Yrs | E46: 15
A47: Take-Out Debt Rate | C47: % | E47: 0.065
A48: Take-Out Debt Leverage | C48: % | E48: 0.59555421
A50: Take Out Debt is to be structrued with a mortgage style amortization with
A51: equal debt service amounts over the entire take-out term of 15 years
A53: In addition to the capital cost from the EPC contract and the Development Fee Bonus
...

Sheet Residual
A1: In Class Case Study Model
A3: Technology | C3: Wind Energy Turbine
A5: Capacity | C5: =+'[1]Base Data'!D5 -> MW | E5: =VLOOKUP(Residual!A5,Table1[#All],8,FALSE) -> 80
A6: Capacity Factor: Note 2 | C6: =+'[1]Base Data'!D15 -> % | E6: =VLOOKUP(Residual!A6,Table1[#All],8,FALSE) -> 0.4
A7: Annual Production | C7: MWH | E7: =+E5*8760*E6 -> 280320
A8: Heat Rate/Fuel Rate | C8: btu/kwh | E8: =VLOOKUP(Residual!A8,Table1[#All],8,FALSE) -> 0
A9: Fixed O&M | C9: $/kw/yr | E9: =VLOOKUP(Residual!A9,Table1[#All],8,FALSE) -> 42
A10: Variable O&M | C10: $/mwh | E10: =VLOOKUP(Residual!A10,Table1[#All],8,FALSE) -> 0
A11: Capital Cost: Note 1 | C11: =+'[1]Base Data'!D6 -> $/kw | E11: =VLOOKUP(Residual!A11,Table1[#All],8,FALSE) -> 1500
A12: EPC Capital Cost* | C12: $mm | E12: =+E5*E11*1000/1000000 -> 120
A13: Construction Debt Term | C13: Yrs | E13: =VLOOKUP(Residual!A13,Table1[#All],8,FALSE) -> 3
A14: S Curve for EPC Capital Cost* | C14: Yr | E14: Y1 | F14: Yr2 | G14: Yr3
A15: S Curve for EPC Capital Cost* | C15: % | E15: 0.1 | F15: 0.4 | G15: 0.5
A16: S Curve for EPC Capital Cost* | C16: $mm | E16: =+E12*E15 -> 12 | F16: =+E12*F15 -> 48 | G16: =+E12*G15 -> 60
A17: Cost Inflation Rate | C17: % | E17: =VLOOKUP(Residual!A17,Table1[#All],8,FALSE) -> 0.025
A18: Economic Life | C18: Years | E18: =VLOOKUP(Residual!A18,Table1[#All],8,FALSE) -> 25
A19: Tax Rate | C19: Federal | E19: =VLOOKUP(Residual!A19,Table1[#All],8,FALSE) -> 0.21
A20: Tax Depreciation | C20: MACRS | E20: =VLOOKUP(Residual!A20,Table1[#All],8,FALSE) -> 5 | H20: Year 1 | I20: Year 2 | J20: Year 3 | K20: Year 4 | L20: Year 5 | M20: Year 6
A21: Tax Depreciation Rate | C21: % | H21: 0.2 | I21: 0.32 | J21: 0.192 | K21: 0.1152 | L21: 0.1152 | M21: 0.0576
A22: CO2 Emissions | C22: lbs/mmbtu | E22: 0
A23: Potential Carbon Tax | C23: $/ton | E23: 0
A25: *Excludes any development fee or interest during construction
A28: Development Fee Bonus
A30: Development Fee Bonus | C30: % EPC Capital Cost | E30: 0.05
A31: Development Fee Bonus | C31: $mm | E31: =+E30*E12 -> 6
A32: Capital Cost Including Development Fee | E32: =+E12+E31 -> 126
A33: S Curve for Total Capital Cost** | C33: Yr | E33: Yr1 | F33: Yr2 | G33: Yr3
A34: S Curve for Total Capital Cost** | C34: % | E34: 0.1 | F34: 0.4 | G34: 0.5
A35: S Curve for Total Capital Cost** | C35: $mm | E35: =+E34*$E$32 -> 12.6 | F35: =+F34*$E$32 -> 50.4 | G35: =+G34*$E$32 -> 63
A37: **Includes development fee but excludes interest during construction
A40: Construction Finance and Take Out Finance
A42: Construction Debt Term | C42: Yrs | E42: 3
A43: Construction Debt Rate | C43: % | E43: 0.05
A44: Construction Debt Leverage | C44: % | E44: 0.5
A46: Take-Out Debt Term | C46: Yrs | E46: 15
A47: Take-Out Debt Rate | C47: % | E47: 0.065
A48: Take-Out Debt Leverage | C48: % | E48: 0.59555421
A50: Take Out Debt is to be structrued with a mortgage style amortization with
A51: equal debt service amounts over the entire take-out term of 15 years
A53: In addition to the capital cost from the EPC contract and the Development Fee Bonus
...

Sheet CCGT Model 
A1: In Class Case Study Model
A3: Technology | C3: Wind Energy Turbine
A5: Capacity | C5: =+'[1]Base Data'!D5 -> MW | E5: =VLOOKUP('CCGT Model '!A5,Table1[#All],8,FALSE) -> 80
A6: Capacity Factor: Note 2 | C6: =+'[1]Base Data'!D15 -> % | E6: =VLOOKUP('CCGT Model '!A6,Table1[#All],8,FALSE) -> 0.4
A7: Annual Production | C7: MWH | E7: =+E5*8760*E6 -> 280320
A8: Heat Rate/Fuel Rate | C8: btu/kwh | E8: =VLOOKUP('CCGT Model '!A8,Table1[#All],8,FALSE) -> 0
A9: Fixed O&M | C9: $/kw/yr | E9: =VLOOKUP('CCGT Model '!A9,Table1[#All],8,FALSE) -> 42
A10: Variable O&M | C10: $/mwh | E10: =VLOOKUP('CCGT Model '!A10,Table1[#All],8,FALSE) -> 0
A11: Capital Cost: Note 1 | C11: =+'[1]Base Data'!D6 -> $/kw | E11: =VLOOKUP('CCGT Model '!A11,Table1[#All],8,FALSE) -> 1500
A12: EPC Capital Cost* | C12: $mm | E12: =+E5*E11*1000/1000000 -> 120
A13: Construction Debt Term | C13: Yrs | E13: =VLOOKUP('CCGT Model '!A13,Table1[#All],8,FALSE) -> 3
A14: S Curve for EPC Capital Cost* | C14: Yr | E14: Y1 | F14: Yr2 | G14: Yr3
A15: S Curve for EPC Capital Cost* | C15: % | E15: 0.1 | F15: 0.4 | G15: 0.5
A16: S Curve for EPC Capital Cost* | C16: $mm | E16: =+E12*E15 -> 12 | F16: =+E12*F15 -> 48 | G16: =+E12*G15 -> 60
A17: Cost Inflation Rate | C17: % | E17: =VLOOKUP('CCGT Model '!A17,Table1[#All],8,FALSE) -> 0.025
A18: Economic Life | C18: Years | E18: =VLOOKUP('CCGT Model '!A18,Table1[#All],8,FALSE) -> 25
A19: Tax Rate | C19: Federal | E19: =VLOOKUP('CCGT Model '!A19,Table1[#All],8,FALSE) -> 0.21
A20: Tax Depreciation | C20: MACRS | E20: =VLOOKUP('CCGT Model '!A20,Table1[#All],8,FALSE) -> 5 | H20: Year 1 | I20: Year 2 | J20: Year 3 | K20: Year 4 | L20: Year 5 | M20: Year 6
A21: Tax Depreciation Rate | C21: % | H21: 0.2 | I21: 0.32 | J21: 0.192 | K21: 0.1152 | L21: 0.1152 | M21: 0.0576
A22: CO2 Emissions | C22: lbs/mmbtu | E22: 0
A23: Potential Carbon Tax | C23: $/ton | E23: 0
A25: *Excludes any development fee or interest during construction
A28: Development Fee Bonus
A30: Development Fee Bonus | C30: % EPC Capital Cost | E30: 0.05
A31: Development Fee Bonus | C31: $mm | E31: =+E30*E12 -> 6
A32: Capital Cost Including Development Fee | E32: =+E12+E31 -> 126
A33: S Curve for Total Capital Cost** | C33: Yr | E33: Yr1 | F33: Yr2 | G33: Yr3
A34: S Curve for Total Capital Cost** | C34: % | E34: 0.1 | F34: 0.4 | G34: 0.5
A35: S Curve for Total Capital Cost** | C35: $mm | E35: =+E34*$E$32 -> 12.6 | F35: =+F34*$E$32 -> 50.4 | G35: =+G34*$E$32 -> 63
A37: **Includes development fee but excludes interest during construction
A40: Construction Finance and Take Out Finance
A42: Construction Debt Term | C42: Yrs | E42: 3
A43: Construction Debt Rate | C43: % | E43: 0.05
A44: Construction Debt Leverage | C44: % | E44: 0.5
A46: Take-Out Debt Term | C46: Yrs | E46: 15
A47: Take-Out Debt Rate | C47: % | E47: 0.065
A48: Take-Out Debt Leverage | C48: % | E48: 0.59555421
A50: Take Out Debt is to be structrued with a mortgage style amortization with
A51: equal debt service amounts over the entire take-out term of 15 years
A53: In addition to the capital cost from the EPC contract and the Development Fee Bonus
...

Sheet Case Study Base Data
A1: Column1 | B1: Column2 | C1: Column3 | D1: Column4 | E1: Column5 | F1: Column6 | G1: Column7 | H1: Column8 | I1: Column9 | J1: Column10 | K1: Column11 | L1: Column12
A2: Case Study Base Data | L2: Class Case Study
J3: Natural Gas | L3: Natural Gas
A4: Technology | D4: Units | F4: Solar | H4: Wind | J4: NG CT | L4: NG CCGT
A6: Capacity Units | D6: MW | F6: MW | H6: MW | J6: MW | L6: MW
A7: Capacity | F7: 80 | H7: 80 | J7: 100 | L7: 700
A8: Location | F8: Arizona | H8: Texas | J8: Texas | L8: Texas
A9: Capital Cost: Note 1 | D9: $/kw | F9: 1000 | H9: 1500 | J9: 1000 | L9: 1000
A10: Heat Rate/Fuel Rate | D10: btu/kwh | F10: 0 | H10: 0 | J10: 9600 | L10: 6400
A11: Fixed O&M | D11: $/kw/yr | F11: 13 | H11: 42 | J11: 12 | L11: 11
A12: Variable O&M | D12: $/mwh | F12: 0 | H12: 0 | J12: 7 | L12: 3
A13: Lead Time | D13: Years | F13: 3 | H13: 3 | J13: 3 | L13: 3
A14: S Curve Year One | B14: Yr 1 | D14: % | F14: 0.1 | H14: 0.1 | J14: 0.2 | L14: 0.2
A15: S Curve Year Two | B15: Yr 2 | D15: % | F15: 0.2 | H15: 0.4 | J15: 0.6 | L15: 0.7
A16: S Curve Year Three | B16: Yr 3 | D16: % | F16: 0.7 | H16: 0.5 | J16: 0.2 | L16: 0.1
A17: Capacity Factor: Note 2 | D17: % | F17: 0.24 | H17: 0.4 | J17: 0.2 | L17: 0.9
A18: Fuel Costs: Note 3 | D18: $/mmbtu | F18: 0 | H18: 0 | J18: 4.5 | L18: 4.5
A19: Economic Life | D19: Years | F19: 25 | H19: 25 | J19: 25 | L19: 25
A20: Tax Depreciation | D20: Note 3 | F20: 5 | H20: 5 | J20: 15 | L20: 15
A21: Price Inflation Rate | D21: % | F21: 0.025 | H21: 0.025 | J21: 0.025 | L21: 0.025
A22: Cost Inflation Rate | D22: % | F22: 0.025 | H22: 0.025 | J22: 0.025 | L22: 0.025
A23: Tax Credit/ | D23: % | F23: 0.3 | H23: 0.3 | J23: 0 | L23: 0
A24: Tax Rate | D24: Federal | F24: 0.21 | H24: 0.21 | J24: 0.21 | L24: 0.21
A25: Construction Debt Term | D25: Yrs | F25: 3 | H25: 3 | J25: 3 | L25: 3
A26: Construction Debt Rate | D26: % | F26: 0.05 | H26: 0.05 | J26: 0.05 | L26: 0.05
A27: Construction Debt Leverage | D27: % | F27: 0.5 | H27: 0.5 | J27: 0.5 | L27: 0.5
A28: Take-Out Debt Term | D28: Yrs | F28: 15 | H28: 15 | J28: 15 | L28: 15
... A31: Development Fee | D31: % | F31: 0.05 | H31: 0.05 | J31: 0.05 | L31: 0.05
A33: Note 1 | B33: EPC Cost including contingency but excluding the Development Fee ----- Start of S Curve 2025
A34: Note 2 | B34: Tucson Az Use PV Watts to check the capacity factor
A35: Note 3 | B35: Solar, Wind | D35: MACRS | E35: 5 | F35: Yr 1 | G35: Yr 2 | H35: Yr 3 | I35: Yr 4 | J35: Yr 5 | K35: Yr 6
F36: 0.2 | G36: 0.32 | H36: 0.192 | I36: 0.1152 | J36: 0.1152 | K36: 0.0576
B37: GT, CCGT | D37: MACRS | E37: 15 | F37: Yr 1 | G37: Yr 2 | H37: Yr 3 | I37: Yr 4 | J37: Yr 5 | K37: Yr 6
F38: 0.05 | G38: 0.095 | H38: 0.0855 | I38: 0.077 | J38: 0.0693 | K38: 0.0623
F39: Yr 11 | G39: Yr 12 | H39: Yr 13 | I39: Yr 14 | J39: Yr 15 | K39: Yr 16
F40: 0.0591 | G40: 0.059 | H40: 0.0591 | I40: 0.059 | J40: 0.0591 | K40: 0.0295
